Workbook

Sheet Sheet1
A1: Table Name | B1: Count | C1: Temp | D1: batch no.
A2: PS_AP_ARC_EXP_DL_H | B2: 0 | C2: APVCHRXX | D2: 100
A3: PS_AP_ARC_VCHL_M_H | B3: 82946 | C3: APVCHRXX | D3: 100
A4: PS_AP_ARC_VCHL_E_H | B4: 0 | C4: APVCHRXX | D4: 100
A5: PS_AP_ARC_VCH_ST_H | B5: 51160 | C5: APVCHRXX | D5: 100
A6: PS_AP_ARC_VCH_UT_H | B6: 51333 | C6: APVCHRXX | D6: 100
A7: PS_AP_ARC_VCH_LN_H | B7: 654395 | C7: APVCHRXX | D7: 100
A8: PS_LNWTHD_UPD_H_XX | B8: 0 | C8: APVCHRXX | D8: 100
A9: PS_VED_DUPINV_H_XX | B9: 0 | C9: APVCHRXX | D9: 100
A10: PS_PAY_TRNSMT_H_XX | B10: 892 | C10: APPYTTXX | D10: 94
A11: PS_AR_FRMLIN2_XX_H | B11: 0 | C11: ARBUR_XX | D11: 97
A12: PS_AR_FORMTMP_XX_H | B12: 0 | C12: ARBUR_XX | D12: 97
A13: PS_AR_FORMNAR_XX_H | B13: 0 | C13: ARBUR_XX | D13: 97
... A617: PS_TLRTSACTXX_H_XX | B617: 0 | C617: TLRTS_XX | D617: 65

Sheet Sheet2
A1: Table Name | B1: Delete count | D1: PRD EXP Count | F1: Count compare
A2: PS_AP_ARC_BCH_XR_H | B2: 0 | D2: =IF(COUNTIF(Sheet4!A:A,A2)>0,VLOOKUP(A2,Sheet4!A:B,2,FALSE),"NotFound") -> 0 | F2: =IF(B2=D2,"Matching","mis match") -> Matching
A3: PS_AP_ARC_DIST_L_H | B3: 1124091 | D3: =IF(COUNTIF(Sheet4!A:A,A3)>0,VLOOKUP(A3,Sheet4!A:B,2,FALSE),"NotFound") -> 1124091 | F3: =IF(B3=D3,"Matching","mis match") -> Matching
A4: PS_AP_ARC_DIST_N_H | B4: 0 | D4: =IF(COUNTIF(Sheet4!A:A,A4)>0,VLOOKUP(A4,Sheet4!A:B,2,FALSE),"NotFound") -> 0 | F4: =IF(B4=D4,"Matching","mis match") -> Matching
A5: PS_AP_ARC_EXP_DL_H | B5: 0 | D5: =IF(COUNTIF(Sheet4!A:A,A5)>0,VLOOKUP(A5,Sheet4!A:B,2,FALSE),"NotFound") -> 0 | F5: =IF(B5=D5,"Matching","mis match") -> Matching
A6: PS_AP_ARC_PY_MSG_H | B6: 20 | D6: =IF(COUNTIF(Sheet4!A:A,A6)>0,VLOOKUP(A6,Sheet4!A:B,2,FALSE),"NotFound") -> 20 | F6: =IF(B6=D6,"Matching","mis match") -> Matching
A7: PS_AP_ARC_PYM_AD_H | B7: 442649 | D7: =IF(COUNTIF(Sheet4!A:A,A7)>0,VLOOKUP(A7,Sheet4!A:B,2,FALSE),"NotFound") -> 442649 | F7: =IF(B7=D7,"Matching","mis match") -> Matching
A8: PS_AP_ARC_PYM_RC_H | B8: 403197 | D8: =IF(COUNTIF(Sheet4!A:A,A8)>0,VLOOKUP(A8,Sheet4!A:B,2,FALSE),"NotFound") -> 403197 | F8: =IF(B8=D8,"Matching","mis match") -> Matching
A9: PS_AP_ARC_PYM_TB_H | B9: 402580 | D9: =IF(COUNTIF(Sheet4!A:A,A9)>0,VLOOKUP(A9,Sheet4!A:B,2,FALSE),"NotFound") -> 402580 | F9: =IF(B9=D9,"Matching","mis match") -> Matching
A10: PS_AP_ARC_PYM_WT_H | B10: 19568 | D10: =IF(COUNTIF(Sheet4!A:A,A10)>0,VLOOKUP(A10,Sheet4!A:B,2,FALSE),"NotFound") -> 19568 | F10: =IF(B10=D10,"Matching","mis match") -> Matching
A11: PS_AP_ARC_PYM_XR_H | B11: 579392 | D11: =IF(COUNTIF(Sheet4!A:A,A11)>0,VLOOKUP(A11,Sheet4!A:B,2,FALSE),"NotFound") -> 579392 | F11: =IF(B11=D11,"Matching","mis match") -> Matching
A12: PS_AP_ARC_VCH_AC_H | B12: 5181089 | D12: =IF(COUNTIF(Sheet4!A:A,A12)>0,VLOOKUP(A12,Sheet4!A:B,2,FALSE),"NotFound") -> 5181089 | F12: =IF(B12=D12,"Matching","mis match") -> Matching
A13: PS_AP_ARC_VCH_DO_H | B13: 0 | D13: =IF(COUNTIF(Sheet4!A:A,A13)>0,VLOOKUP(A13,Sheet4!A:B,2,FALSE),"NotFound") -> 0 | F13: =IF(B13=D13,"Matching","mis match") -> Matching
... A543: PS_WTHD_UPDT_H_XX | B543: 0 | D543: =IF(COUNTIF(Sheet4!A:A,A543)>0,VLOOKUP(A543,Sheet4!A:B,2,FALSE),"NotFound") -> 0 | F543: =IF(B543=D543,"Matching","mis match") -> Matching
A544: (blank) | D544: =IF(COUNTIF(Sheet4!A:A,A544)>0,VLOOKUP(A544,Sheet4!A:B,2,FALSE),"NotFound") -> 0 | F544: =IF(B544=D544,"Matching","mis match") -> Matching
A545: GrandTotal | B545: 155039757

Sheet Sheet3
A1: PRD EXP table name | B1: count
A2: PS_CUSTAGINGX_H_XX | B2: 0
A3: PS_AP_ARC_PYM_TB_H | B3: 402580
A4: PS_WTH_TRXTBL_H_XX | B4: 14674
A5: PS_AP_SUPPRES_H_XX | B5: 0
A6: PS_PAYMNT_TBL_H_XX | B6: 402580
A7: PS_PYMNT_ADVC_H_XX | B7: 26515
A8: PS_AP_ARC_PYM_RC_H | B8: 403197
A9: PS_AP_ARC_PYM_AD_H | B9: 442649
A10: PS_PAY_TRNSMT_H_XX | B10: 892
A11: PS_AP_ARC_VCH_AC_H | B11: 5181089
A12: PS_UNMTCH_TMP_H_XX | B12: 19
A13: PS_AP_ARC_VCHL_M_H | B13: 82946
... A576: PS_VMSTRNSHST_H_XX | B576: 0

Sheet Sheet4
A1: Table name | B1: Exported count
A2: PS_AP_ARC_BCH_XR_H | B2: 0
A3: PS_AP_ARC_DIST_L_H | B3: 1124091
A4: PS_AP_ARC_DIST_N_H | B4: 0
A5: PS_AP_ARC_EXP_DL_H | B5: 0
A6: PS_AP_ARC_PY_MSG_H | B6: 20
A7: PS_AP_ARC_PYM_AD_H | B7: 442649
A8: PS_AP_ARC_PYM_RC_H | B8: 403197
A9: PS_AP_ARC_PYM_TB_H | B9: 402580
A10: PS_AP_ARC_PYM_WT_H | B10: 19568
A11: PS_AP_ARC_PYM_XR_H | B11: 579392
A12: PS_AP_ARC_VCH_AC_H | B12: 5181089
A13: PS_AP_ARC_VCH_DO_H | B13: 0
... A543: PS_WTHD_UPDT_H_XX | B543: 0
A544: (blank)
A545: Grand Total | B545: 155039757

Sheet Generic 2
A1: Table Name | B1: Deleted Count | G1: Table Name | H1: Count | J1: PRD EXP Count | K1: count compare
A2: PS_AP_ARC_BCH_XR_H | B2: 0 | D2: 100 | G2: PS_AP_ARC_EXP_DL_H | H2: 0 | J2: =IF(COUNTIF(Sheet4!A:A,A2)>0,VLOOKUP(A2,Sheet4!A:B,2,FALSE),"NotFound") -> 0 | K2: =IF(B2=J2,"Match","Mis Match") -> Match
A3: PS_AP_ARC_DIST_L_H | B3: 1124091 | D3: 100 | G3: PS_AP_ARC_VCHL_M_H | H3: 82946 | J3: =IF(COUNTIF(Sheet4!A:A,A3)>0,VLOOKUP(A3,Sheet4!A:B,2,FALSE),"NotFound") -> 1124091 | K3: =IF(B3=J3,"Match","Mis Match") -> Match
A4: PS_AP_ARC_DIST_N_H | B4: 0 | D4: 100 | G4: PS_AP_ARC_VCHL_E_H | H4: 0 | J4: =IF(COUNTIF(Sheet4!A:A,A4)>0,VLOOKUP(A4,Sheet4!A:B,2,FALSE),"NotFound") -> 0 | K4: =IF(B4=J4,"Match","Mis Match") -> Match
A5: PS_AP_ARC_EXP_DL_H | B5: 0 | D5: 100 | G5: PS_AP_ARC_VCH_ST_H | H5: 51160 | J5: =IF(COUNTIF(Sheet4!A:A,A5)>0,VLOOKUP(A5,Sheet4!A:B,2,FALSE),"NotFound") -> 0 | K5: =IF(B5=J5,"Match","Mis Match") -> Match
A6: PS_AP_ARC_PY_MSG_H | B6: 20 | D6: 100 | G6: PS_AP_ARC_VCH_UT_H | H6: 51333 | J6: =IF(COUNTIF(Sheet4!A:A,A6)>0,VLOOKUP(A6,Sheet4!A:B,2,FALSE),"NotFound") -> 20 | K6: =IF(B6=J6,"Match","Mis Match") -> Match
A7: PS_AP_ARC_PYM_AD_H | B7: 442649 | D7: 100 | G7: PS_AP_ARC_VCH_LN_H | H7: 654395 | J7: =IF(COUNTIF(Sheet4!A:A,A7)>0,VLOOKUP(A7,Sheet4!A:B,2,FALSE),"NotFound") -> 442649 | K7: =IF(B7=J7,"Match","Mis Match") -> Match
A8: PS_AP_ARC_PYM_RC_H | B8: 403197 | D8: 100 | G8: PS_LNWTHD_UPD_H_XX | H8: 0 | J8: =IF(COUNTIF(Sheet4!A:A,A8)>0,VLOOKUP(A8,Sheet4!A:B,2,FALSE),"NotFound") -> 403197 | K8: =IF(B8=J8,"Match","Mis Match") -> Match
A9: PS_AP_ARC_PYM_TB_H | B9: 402580 | D9: 100 | G9: PS_VED_DUPINV_H_XX | H9: 0 | J9: =IF(COUNTIF(Sheet4!A:A,A9)>0,VLOOKUP(A9,Sheet4!A:B,2,FALSE),"NotFound") -> 402580 | K9: =IF(B9=J9,"Match","Mis Match") -> Match
A10: PS_AP_ARC_PYM_WT_H | B10: 19568 | D10: 94 | G10: PS_PAY_TRNSMT_H_XX | H10: 892 | J10: =IF(COUNTIF(Sheet4!A:A,A10)>0,VLOOKUP(A10,Sheet4!A:B,2,FALSE),"NotFound") -> 19568 | K10: =IF(B10=J10,"Match","Mis Match") -> Match
A11: PS_AP_ARC_PYM_XR_H | B11: 579392 | D11: 97 | G11: PS_AR_FRMLIN2_XX_H | H11: 0 | J11: =IF(COUNTIF(Sheet4!A:A,A11)>0,VLOOKUP(A11,Sheet4!A:B,2,FALSE),"NotFound") -> 579392 | K11: =IF(B11=J11,"Match","Mis Match") -> Match
A12: PS_AP_ARC_VCH_AC_H | B12: 5181089 | D12: 97 | G12: PS_AR_FORMTMP_XX_H | H12: 0 | J12: =IF(COUNTIF(Sheet4!A:A,A12)>0,VLOOKUP(A12,Sheet4!A:B,2,FALSE),"NotFound") -> 5181089 | K12: =IF(B12=J12,"Match","Mis Match") -> Match
A13: PS_AP_ARC_VCH_DO_H | B13: 0 | D13: 97 | G13: PS_AR_FORMNAR_XX_H | H13: 0 | J13: =IF(COUNTIF(Sheet4!A:A,A13)>0,VLOOKUP(A13,Sheet4!A:B,2,FALSE),"NotFound") -> 0 | K13: =IF(B13=J13,"Match","Mis Match") -> Match
... A18: PS_AP_ARC_VCH_RM_H | B18: 0 | D18: 96 | G18: PS_AR_PEND_IT_MR_H | H18: 0 | J18: =IF(COUNTIF(Sheet4!A:A,A18)>0,VLOOKUP(A18,Sheet4!A:B,2,FALSE),"NotFound") -> 0 | K18: =IF(B18=J18,"Match","Mis Match") -> Match
A19: PS_AP_ARC_VCH_ST_H | B19: 51160 | C19: ARPEND, | D19: 96 | G19: PS_AR_PEND_VAT_H | H19: 0 | J19: =IF(COUNTIF(Sheet4!A:A,A19)>0,VLOOKUP(A19,Sheet4!A:B,2,FALSE),"NotFound") -> 51160 | K19: =IF(B19=J19,"Match","Mis Match") -> Match
A20: PS_AP_ARC_VCH_TG_H | B20: 0 | C20: ARPO_XX, | D20: 72 | G20: PS_AR_PO_FLDS_XX_H | H20: 0 | J20: =IF(COUNTIF(Sheet4!A:A,A20)>0,VLOOKUP(A20,Sheet4!A:B,2,FALSE),"NotFound") -> 0 | K20: =IF(B20=J20,"Match","Mis Match") -> Match
A21: PS_AP_ARC_VCH_TX_H | B21: 0 | C21: ARRAR_XX, | D21: 105 | G21: PS_AR_FRMRARB_XX_H | H21: 0 | J21: =IF(COUNTIF(Sheet4!A:A,A21)>0,VLOOKUP(A21,Sheet4!A:B,2,FALSE),"NotFound") -> 0 | K21: =IF(B21=J21,"Match","Mis Match") -> Match
A22: PS_AP_ARC_VCH_UT_H | B22: 51333 | C22: ARSTMT, | D22: 3 | G22: PS_AR_STMT_CUST_H | H22: 6460 | J22: =IF(COUNTIF(Sheet4!A:A,A22)>0,VLOOKUP(A22,Sheet4!A:B,2,FALSE),"NotFound") -> 51333 | K22: =IF(B22=J22,"Match","Mis Match") -> Match
A23: PS_AP_ARC_VCH_VB_H | B23: 0 | C23: ARTAR_XX, | D23: 106 | G23: PS_AR_FORMTAR_XX_H | H23: 4 | J23: =IF(COUNTIF(Sheet4!A:A,A23)>0,VLOOKUP(A23,Sheet4!A:B,2,FALSE),"NotFound") -> 0 | K23: =IF(B23=J23,"Match","Mis Match") -> Match
A24: PS_AP_ARC_VCH_VI_H | B24: 0 | C24: BICBINXX, | D24: 5 | G24: PS_BICBIVCLIN_H_XX | H24: 0 | J24: =IF(COUNTIF(Sheet4!A:A,A24)>0,VLOOKUP(A24,Sheet4!A:B,2,FALSE),"NotFound") -> 0 | K24: =IF(B24=J24,"Match","Mis Match") -> Match
A25: PS_AP_ARC_VCH_VN_H | B25: 0 | C25: BIINVXX, | D25: 91 | G25: PS_BIACCTENTRY_HXX | H25: 14432815 | J25: =IF(COUNTIF(Sheet4!A:A,A25)>0,VLOOKUP(A25,Sheet4!A:B,2,FALSE),"NotFound") -> 0 | K25: =IF(B25=J25,"Match","Mis Match") -> Match
A26: PS_AP_ARC_VCH_WT_H | B26: 22074 | C26: BIINVXX, | D26: 91 | G26: PS_BIHDRAR_H_XX | H26: 3808639 | J26: =IF(COUNTIF(Sheet4!A:A,A26)>0,VLOOKUP(A26,Sheet4!A:B,2,FALSE),"NotFound") -> 22074 | K26: =IF(B26=J26,"Match","Mis Match") -> Match
A27: PS_AP_ARC_VCHL_E_H | B27: 0 | C27: BIINVXX, | D27: 91 | G27: PS_BIHDRCRCARD_HXX | H27: 0 | J27: =IF(COUNTIF(Sheet4!A:A,A27)>0,VLOOKUP(A27,Sheet4!A:B,2,FALSE),"NotFound") -> 0 | K27: =IF(B27=J27,"Match","Mis Match") -> Match
A28: PS_AP_ARC_VCHL_M_H | B28: 82946 | C28: BIINVXX, | D28: 91 | G28: PS_BILNDSTAR_H_XX | H28: 0 | J28: =IF(COUNTIF(Sheet4!A:A,A28)>0,VLOOKUP(A28,Sheet4!A:B,2,FALSE),"NotFound") -> 82946 | K28: =IF(B28=J28,"Match","Mis Match") -> Match
A29: PS_AP_ARC_VOUCH_H | B29: 566074 | C29: BIINVXX, | D29: 2 | G29: PS_BIACCTENTRY_HXX | H29: 746671 | J29: =IF(COUNTIF(Sheet4!A:A,A29)>0,VLOOKUP(A29,Sheet4!A:B,2,FALSE),"NotFound") -> 566074 | K29: =IF(B29=J29,"Match","Mis Match") -> Match
A30: PS_AP_PYMT_AUD_ARC | B30: 0 | C30: BIINVXX, | D30: 2 | G30: PS_BIALLTAXX_H_XX | H30: 0 | J30: =IF(COUNTIF(Sheet4!A:A,A30)>0,VLOOKUP(A30,Sheet4!A:B,2,FALSE),"NotFound") -> 0 | K30: =IF(B30=J30,"Match","Mis Match") -> Match
... A543: PS_WTHD_UPDT_H_XX | B543: 0 | C543: TLRTS_XX, | D543: 65 | G543: PS_TLRTSPRJXX_H_XX | H543: 0 | J543: =IF(COUNTIF(Sheet4!A:A,A543)>0,VLOOKUP(A543,Sheet4!A:B,2,FALSE),"NotFound") -> 0 | K543: =IF(B543=J543,"Match","Mis Match") -> Match
A544: (blank) | C544: APPYMTXX, | D544: 93 | G544: PS_AP_SUPPRES_H_XX | H544: 0 | J544: =IF(COUNTIF(Sheet4!A:A,A544)>0,VLOOKUP(A544,Sheet4!A:B,2,FALSE),"NotFound") -> 0 | K544: =IF(B544=J544,"Match","Mis Match") -> Match
A545: Grand Total | B545: 155039757 | C545: APVCHRXX, | D545: 100 | G545: PS_AP_ARC_DIST_N_H | H545: 0
C546: APVCHRXX, | D546: 100 | G546: PS_AP_ARC_VCH_TG_H | H546: 0
C547: APVCHRXX, | D547: 100 | G547: PS_AP_ARC_VCH_WT_H | H547: 22074
C548: APVCHRXX, | D548: 100 | G548: PS_TSE_VCHR_H_XX | H548: 0
C549: APVCHRXX, | D549: 100 | G549: PS_DSTRPMTXRF_H_XX | H549: 42
C550: AP_PYMNT, | D550: 13 | G550: PS_AP_ARC_PYM_TB_H | H550: 0
C551: AP_PYMNT, | D551: 13 | G551: PS_WTH_TRXTBL_H_XX | H551: 0
C552: ARBUR_XX, | D552: 97 | G552: PS_AR_FRMLIN1_XX_H | H552: 0
C553: ARPO_XX, | D553: 72 | G553: PS_PO_EXTRACT_XX_H | H553: 0
C554: ARPO_XX, | D554: 72 | G554: PS_AR_PO_PRTF_XX_H | H554: 0
C555: ARPO_XX, | D555: 72 | G555: PS_AR_PO_XX_H | H555: 0
C556: BICANXX, | D556: 64 | G556: PS_BIX24DSTMPX_HXX | H556: 0
...
